Workbook

Sheet Locations
A1: Name | B1: Latitude | C1: Longitude | E1: Source: Google Places geocoding; straight-line (haversine) coordinates.
A2: Stanford Court | B2: 33.651943 | C2: -117.83748
A3: Princeton Court | B3: 33.6524 | C3: -117.8365
A4: Oxford Court | B4: 33.653477 | C4: -117.83813
A5: Ambrose | B5: 33.652996 | C5: -117.83506
A6: Dartmouth Court | B6: 33.6514 | C6: -117.8378
A7: Columbia Court | B7: 33.6494 | C7: -117.8378
A8: Berkeley Court | B8: 33.648954 | C8: -117.83711
A9: Harvard Court | B9: 33.650239 | C9: -117.83455
A10: Cornell Court | B10: 33.651 | C10: -117.8355
A11: Mesa Court | B11: 33.652111 | C11: -117.84465
A12: Middle Earth | B12: 33.644883 | C12: -117.83724
A13: Puerta del Sol | B13: 33.647818 | C13: -117.83304
... A20: Camino del Sol | B20: 33.64449 | C20: -117.82488

Sheet Distance Matrix (ft)
B1: =Locations!A2 -> Stanford Court | C1: =Locations!A3 -> Princeton Court | D1: =Locations!A4 -> Oxford Court | E1: =Locations!A5 -> Ambrose | F1: =Locations!A6 -> Dartmouth Court | G1: =Locations!A7 -> Columbia Court | H1: =Locations!A8 -> Berkeley Court | I1: =Locations!A9 -> Harvard Court | J1: =Locations!A10 -> Cornell Court | K1: =Locations!A11 -> Mesa Court | L1: =Locations!A12 -> Middle Earth | M1: =Locations!A13 -> Puerta del Sol | N1: =Locations!A14 -> Verano | O1: =Locations!A15 -> Arroyo Vista | P1: =Locations!A16 -> Plaza Verde 1 | Q1: =Locations!A17 -> Plaza Verde 2 | R1: =Locations!A18 -> Vista del Campo Norte | S1: =Locations!A19 -> Vista del Campo | T1: =Locations!A20 -> Camino del Sol
A2: =Locations!A2 -> Stanford Court | B2: =0 -> 0 | C2: =ROUND(3958.8*5280*ACOS(MIN(1,MAX(-1,SIN(RADIANS(Locations!$B2))*SIN(RADIANS(Locations!$B3))+COS(RADIANS(Locations!$B2))*COS(RADIANS(Locations!$B3))*COS(RADIANS(Locations!$C3-Locations!$C2))))),0) -> 342 | D2: =ROUND(3958.8*5280*ACOS(MIN(1,MAX(-1,SIN(RADIANS(Locations!$B2))*SIN(RADIANS(Locations!$B4))+COS(RADIANS(Locations!$B2))*COS(RADIANS(Locations!$B4))*COS(RADIANS(Locations!$C4-Locations!$C2))))),0) -> 594 | E2: =ROUND(3958.8*5280*ACOS(MIN(1,MAX(-1,SIN(RADIANS(Locations!$B2))*SIN(RADIANS(Locations!$B5))+COS(RADIANS(Locations!$B2))*COS(RADIANS(Locations!$B5))*COS(RADIANS(Locations!$C5-Locations!$C2))))),0) -> 832 | F2: =ROUND(3958.8*5280*ACOS(MIN(1,MAX(-1,SIN(RADIANS(Locations!$B2))*SIN(RADIANS(Locations!$B6))+COS(RADIANS(Locations!$B2))*COS(RADIANS(Locations!$B6))*COS(RADIANS(Locations!$C6-Locations!$C2))))),0) -> 220 | G2: =ROUND(3958.8*5280*ACOS(MIN(1,MAX(-1,SIN(RADIANS(Locations!$B2))*SIN(RADIANS(Locations!$B7))+COS(RADIANS(Locations!$B2))*COS(RADIANS(Locations!$B7))*COS(RADIANS(Locations!$C7-Locations!$C2))))),0) -> 933 | H2: =ROUND(3958.8*5280*ACOS(MIN(1,MAX(-1,SIN(RADIANS(Locations!$B2))*SIN(RADIANS(Locations!$B8))+COS(RADIANS(Locations!$B2))*COS(RADIANS(Locations!$B8))*COS(RADIANS(Locations!$C8-Locations!$C2))))),0) -> 1096 | I2: =ROUND(3958.8*5280*ACOS(MIN(1,MAX(-1,SIN(RADIANS(Locations!$B2))*SIN(RADIANS(Locations!$B9))+COS(RADIANS(Locations!$B2))*COS(RADIANS(Locations!$B9))*COS(RADIANS(Locations!$C9-Locations!$C2))))),0) -> 1087 | J2: =ROUND(3958.8*5280*ACOS(MIN(1,MAX(-1,SIN(RADIANS(Locations!$B2))*SIN(RADIANS(Locations!$B10))+COS(RADIANS(Locations!$B2))*COS(RADIANS(Locations!$B10))*COS(RADIANS(Locations!$C10-Locations!$C2))))),0) -> 694 | K2: =ROUND(3958.8*5280*ACOS(MIN(1,MAX(-1,SIN(RADIANS(Locations!$B2))*SIN(RADIANS(Locations!$B11))+COS(RADIANS(Locations!$B2))*COS(RADIANS(Locations!$B11))*COS(RADIANS(Locations!$C11-Locations!$C2))))),0) -> 2177 | L2: =ROUND(3958.8*5280*ACOS(MIN(1,MAX(-1,SIN(RADIANS(Locations!$B2))*SIN(RADIANS(Locations!$B12))+COS(RADIANS(Locations!$B2))*COS(RADIANS(Locations!$B12))*COS(RADIANS(Locations!$C12-Locations!$C2))))),0) -> 2577 | M2: =ROUND(3958.8*5280*ACOS(MIN(1,MAX(-1,SIN(RADIANS(Locations!$B2))*SIN(RADIANS(Locations!$B13))+COS(RADIANS(Locations!$B2))*COS(RADIANS(Locations!$B13))*COS(RADIANS(Locations!$C13-Locations!$C2))))),0) -> 2022 | N2: =ROUND(3958.8*5280*ACOS(MIN(1,MAX(-1,SIN(RADIANS(Locations!$B2))*SIN(RADIANS(Locations!$B14))+COS(RADIANS(Locations!$B2))*COS(RADIANS(Locations!$B14))*COS(RADIANS(Locations!$C14-Locations!$C2))))),0) -> 3537 | O2: =ROUND(3958.8*5280*ACOS(MIN(1,MAX(-1,SIN(RADIANS(Locations!$B2))*SIN(RADIANS(Locations!$B15))+COS(RADIANS(Locations!$B2))*COS(RADIANS(Locations!$B15))*COS(RADIANS(Locations!$C15-Locations!$C2))))),0) -> 3186 | P2: =ROUND(3958.8*5280*ACOS(MIN(1,MAX(-1,SIN(RADIANS(Locations!$B2))*SIN(RADIANS(Locations!$B16))+COS(RADIANS(Locations!$B2))*COS(RADIANS(Locations!$B16))*COS(RADIANS(Locations!$C16-Locations!$C2))))),0) -> 2996 | Q2: =ROUND(3958.8*5280*ACOS(MIN(1,MAX(-1,SIN(RADIANS(Locations!$B2))*SIN(RADIANS(Locations!$B17))+COS(RADIANS(Locations!$B2))*COS(RADIANS(Locations!$B17))*COS(RADIANS(Locations!$C17-Locations!$C2))))),0) -> 3297 | R2: =ROUND(3958.8*5280*ACOS(MIN(1,MAX(-1,SIN(RADIANS(Locations!$B2))*SIN(RADIANS(Locations!$B18))+COS(RADIANS(Locations!$B2))*COS(RADIANS(Locations!$B18))*COS(RADIANS(Locations!$C18-Locations!$C2))))),0) -> 4699 | S2: =ROUND(3958.8*5280*ACOS(MIN(1,MAX(-1,SIN(RADIANS(Locations!$B2))*SIN(RADIANS(Locations!$B19))+COS(RADIANS(Locations!$B2))*COS(RADIANS(Locations!$B19))*COS(RADIANS(Locations!$C19-Locations!$C2))))),0) -> 5141 | T2: =ROUND(3958.8*5280*ACOS(MIN(1,MAX(-1,SIN(RADIANS(Locations!$B2))*SIN(RADIANS(Locations!$B20))+COS(RADIANS(Locations!$B2))*COS(RADIANS(Locations!$B20))*COS(RADIANS(Locations!$C20-Locations!$C2))))),0) -> 4696
A3: =Locations!A3 -> Princeton Court | B3: =ROUND(3958.8*5280*ACOS(MIN(1,MAX(-1,SIN(RADIANS(Locations!$B3))*SIN(RADIANS(Locations!$B2))+COS(RADIANS(Locations!$B3))*COS(RADIANS(Locations!$B2))*COS(RADIANS(Locations!$C2-Locations!$C3))))),0) -> 342 | C3: =0 -> 0 | D3: =ROUND(3958.8*5280*ACOS(MIN(1,MAX(-1,SIN(RADIANS(Locations!$B3))*SIN(RADIANS(Locations!$B4))+COS(RADIANS(Locations!$B3))*COS(RADIANS(Locations!$B4))*COS(RADIANS(Locations!$C4-Locations!$C3))))),0) -> 633 | E3: =ROUND(3958.8*5280*ACOS(MIN(1,MAX(-1,SIN(RADIANS(Locations!$B3))*SIN(RADIANS(Locations!$B5))+COS(RADIANS(Locations!$B3))*COS(RADIANS(Locations!$B5))*COS(RADIANS(Locations!$C5-Locations!$C3))))),0) -> 489 | F3: =ROUND(3958.8*5280*ACOS(MIN(1,MAX(-1,SIN(RADIANS(Locations!$B3))*SIN(RADIANS(Locations!$B6))+COS(RADIANS(Locations!$B3))*COS(RADIANS(Locations!$B6))*COS(RADIANS(Locations!$C6-Locations!$C3))))),0) -> 538 | G3: =ROUND(3958.8*5280*ACOS(MIN(1,MAX(-1,SIN(RADIANS(Locations!$B3))*SIN(RADIANS(Locations!$B7))+COS(RADIANS(Locations!$B3))*COS(RADIANS(Locations!$B7))*COS(RADIANS(Locations!$C7-Locations!$C3))))),0) -> 1163 | H3: =ROUND(3958.8*5280*ACOS(MIN(1,MAX(-1,SIN(RADIANS(Locations!$B3))*SIN(RADIANS(Locations!$B8))+COS(RADIANS(Locations!$B3))*COS(RADIANS(Locations!$B8))*COS(RADIANS(Locations!$C8-Locations!$C3))))),0) -> 1271 | I3: =ROUND(3958.8*5280*ACOS(MIN(1,MAX(-1,SIN(RADIANS(Locations!$B3))*SIN(RADIANS(Locations!$B9))+COS(RADIANS(Locations!$B3))*COS(RADIANS(Locations!$B9))*COS(RADIANS(Locations!$C9-Locations!$C3))))),0) -> 986 | J3: =ROUND(3958.8*5280*ACOS(MIN(1,MAX(-1,SIN(RADIANS(Locations!$B3))*SIN(RADIANS(Locations!$B10))+COS(RADIANS(Locations!$B3))*COS(RADIANS(Locations!$B10))*COS(RADIANS(Locations!$C10-Locations!$C3))))),0) -> 594 | K3: =ROUND(3958.8*5280*ACOS(MIN(1,MAX(-1,SIN(RADIANS(Locations!$B3))*SIN(RADIANS(Locations!$B11))+COS(RADIANS(Locations!$B3))*COS(RADIANS(Locations!$B11))*COS(RADIANS(Locations!$C11-Locations!$C3))))),0) -> 2478 | L3: =ROUND(3958.8*5280*ACOS(MIN(1,MAX(-1,SIN(RADIANS(Locations!$B3))*SIN(RADIANS(Locations!$B12))+COS(RADIANS(Locations!$B3))*COS(RADIANS(Locations!$B12))*COS(RADIANS(Locations!$C12-Locations!$C3))))),0) -> 2752 | M3: =ROUND(3958.8*5280*ACOS(MIN(1,MAX(-1,SIN(RADIANS(Locations!$B3))*SIN(RADIANS(Locations!$B13))+COS(RADIANS(Locations!$B3))*COS(RADIANS(Locations!$B13))*COS(RADIANS(Locations!$C13-Locations!$C3))))),0) -> 1975 | N3: =ROUND(3958.8*5280*ACOS(MIN(1,MAX(-1,SIN(RADIANS(Locations!$B3))*SIN(RADIANS(Locations!$B14))+COS(RADIANS(Locations!$B3))*COS(RADIANS(Locations!$B14))*COS(RADIANS(Locations!$C14-Locations!$C3))))),0) -> 3501 | O3: =ROUND(3958.8*5280*ACOS(MIN(1,MAX(-1,SIN(RADIANS(Locations!$B3))*SIN(RADIANS(Locations!$B15))+COS(RADIANS(Locations!$B3))*COS(RADIANS(Locations!$B15))*COS(RADIANS(Locations!$C15-Locations!$C3))))),0) -> 3060 | P3: =ROUND(3958.8*5280*ACOS(MIN(1,MAX(-1,SIN(RADIANS(Locations!$B3))*SIN(RADIANS(Locations!$B16))+COS(RADIANS(Locations!$B3))*COS(RADIANS(Locations!$B16))*COS(RADIANS(Locations!$C16-Locations!$C3))))),0) -> 2838 | Q3: =ROUND(3958.8*5280*ACOS(MIN(1,MAX(-1,SIN(RADIANS(Locations!$B3))*SIN(RADIANS(Locations!$B17))+COS(RADIANS(Locations!$B3))*COS(RADIANS(Locations!$B17))*COS(RADIANS(Locations!$C17-Locations!$C3))))),0) -> 3136 | R3: =ROUND(3958.8*5280*ACOS(MIN(1,MAX(-1,SIN(RADIANS(Locations!$B3))*SIN(RADIANS(Locations!$B18))+COS(RADIANS(Locations!$B3))*COS(RADIANS(Locations!$B18))*COS(RADIANS(Locations!$C18-Locations!$C3))))),0) -> 4508 | S3: =ROUND(3958.8*5280*ACOS(MIN(1,MAX(-1,SIN(RADIANS(Locations!$B3))*SIN(RADIANS(Locations!$B19))+COS(RADIANS(Locations!$B3))*COS(RADIANS(Locations!$B19))*COS(RADIANS(Locations!$C19-Locations!$C3))))),0) -> 4988 | T3: =ROUND(3958.8*5280*ACOS(MIN(1,MAX(-1,SIN(RADIANS(Locations!$B3))*SIN(RADIANS(Locations!$B20))+COS(RADIANS(Locations!$B3))*COS(RADIANS(Locations!$B20))*COS(RADIANS(Locations!$C20-Locations!$C3))))),0) -> 4559
A4: =Locations!A4 -> Oxford Court | B4: =ROUND(3958.8*5280*ACOS(MIN(1,MAX(-1,SIN(RADIANS(Locations!$B4))*SIN(RADIANS(Locations!$B2))+COS(RADIANS(Locations!$B4))*COS(RADIANS(Locations!$B2))*COS(RADIANS(Locations!$C2-Locations!$C4))))),0) -> 594 | C4: =ROUND(3958.8*5280*ACOS(MIN(1,MAX(-1,SIN(RADIANS(Locations!$B4))*SIN(RADIANS(Locations!$B3))+COS(RADIANS(Locations!$B4))*COS(RADIANS(Locations!$B3))*COS(RADIANS(Locations!$C3-Locations!$C4))))),0) -> 633 | D4: =0 -> 0 | E4: =ROUND(3958.8*5280*ACOS(MIN(1,MAX(-1,SIN(RADIANS(Locations!$B4))*SIN(RADIANS(Locations!$B5))+COS(RADIANS(Locations!$B4))*COS(RADIANS(Locations!$B5))*COS(RADIANS(Locations!$C5-Locations!$C4))))),0) -> 951 | F4: =ROUND(3958.8*5280*ACOS(MIN(1,MAX(-1,SIN(RADIANS(Locations!$B4))*SIN(RADIANS(Locations!$B6))+COS(RADIANS(Locations!$B4))*COS(RADIANS(Locations!$B6))*COS(RADIANS(Locations!$C6-Locations!$C4))))),0) -> 765 | G4: =ROUND(3958.8*5280*ACOS(MIN(1,MAX(-1,SIN(RADIANS(Locations!$B4))*SIN(RADIANS(Locations!$B7))+COS(RADIANS(Locations!$B4))*COS(RADIANS(Locations!$B7))*COS(RADIANS(Locations!$C7-Locations!$C4))))),0) -> 1491 | H4: =ROUND(3958.8*5280*ACOS(MIN(1,MAX(-1,SIN(RADIANS(Locations!$B4))*SIN(RADIANS(Locations!$B8))+COS(RADIANS(Locations!$B4))*COS(RADIANS(Locations!$B8))*COS(RADIANS(Locations!$C8-Locations!$C4))))),0) -> 1679 | I4: =ROUND(3958.8*5280*ACOS(MIN(1,MAX(-1,SIN(RADIANS(Locations!$B4))*SIN(RADIANS(Locations!$B9))+COS(RADIANS(Locations!$B4))*COS(RADIANS(Locations!$B9))*COS(RADIANS(Locations!$C9-Locations!$C4))))),0) -> 1606 | J4: =ROUND(3958.8*5280*ACOS(MIN(1,MAX(-1,SIN(RADIANS(Locations!$B4))*SIN(RADIANS(Locations!$B10))+COS(RADIANS(Locations!$B4))*COS(RADIANS(Locations!$B10))*COS(RADIANS(Locations!$C10-Locations!$C4))))),0) -> 1207 | K4: =ROUND(3958.8*5280*ACOS(MIN(1,MAX(-1,SIN(RADIANS(Locations!$B4))*SIN(RADIANS(Locations!$B11))+COS(RADIANS(Locations!$B4))*COS(RADIANS(Locations!$B11))*COS(RADIANS(Locations!$C11-Locations!$C4))))),0) -> 2041 | L4: =ROUND(3958.8*5280*ACOS(MIN(1,MAX(-1,SIN(RADIANS(Locations!$B4))*SIN(RADIANS(Locations!$B12))+COS(RADIANS(Locations!$B4))*COS(RADIANS(Locations!$B12))*COS(RADIANS(Locations!$C12-Locations!$C4))))),0) -> 3147 | M4: =ROUND(3958.8*5280*ACOS(MIN(1,MAX(-1,SIN(RADIANS(Locations!$B4))*SIN(RADIANS(Locations!$B13))+COS(RADIANS(Locations!$B4))*COS(RADIANS(Locations!$B13))*COS(RADIANS(Locations!$C13-Locations!$C4))))),0) -> 2581 | N4: =ROUND(3958.8*5280*ACOS(MIN(1,MAX(-1,SIN(RADIANS(Locations!$B4))*SIN(RADIANS(Locations!$B14))+COS(RADIANS(Locations!$B4))*COS(RADIANS(Locations!$B14))*COS(RADIANS(Locations!$C14-Locations!$C4))))),0) -> 4104 | O4: =ROUND(3958.8*5280*ACOS(MIN(1,MAX(-1,SIN(RADIANS(Locations!$B4))*SIN(RADIANS(Locations!$B15))+COS(RADIANS(Locations!$B4))*COS(RADIANS(Locations!$B15))*COS(RADIANS(Locations!$C15-Locations!$C4))))),0) -> 3692 | P4: =ROUND(3958.8*5280*ACOS(MIN(1,MAX(-1,SIN(RADIANS(Locations!$B4))*SIN(RADIANS(Locations!$B16))+COS(RADIANS(Locations!$B4))*COS(RADIANS(Locations!$B16))*COS(RADIANS(Locations!$C16-Locations!$C4))))),0) -> 3471 | Q4: =ROUND(3958.8*5280*ACOS(MIN(1,MAX(-1,SIN(RADIANS(Locations!$B4))*SIN(RADIANS(Locations!$B17))+COS(RADIANS(Locations!$B4))*COS(RADIANS(Locations!$B17))*COS(RADIANS(Locations!$C17-Locations!$C4))))),0) -> 3769 | R4: =ROUND(3958.8*5280*ACOS(MIN(1,MAX(-1,SIN(RADIANS(Locations!$B4))*SIN(RADIANS(Locations!$B18))+COS(RADIANS(Locations!$B4))*COS(RADIANS(Locations!$B18))*COS(RADIANS(Locations!$C18-Locations!$C4))))),0) -> 5134 | S4: =ROUND(3958.8*5280*ACOS(MIN(1,MAX(-1,SIN(RADIANS(Locations!$B4))*SIN(RADIANS(Locations!$B19))+COS(RADIANS(Locations!$B4))*COS(RADIANS(Locations!$B19))*COS(RADIANS(Locations!$C19-Locations!$C4))))),0) -> 5620 | T4: =ROUND(3958.8*5280*ACOS(MIN(1,MAX(-1,SIN(RADIANS(Locations!$B4))*SIN(RADIANS(Locations!$B20))+COS(RADIANS(Locations!$B4))*COS(RADIANS(Locations!$B20))*COS(RADIANS(Locations!$C20-Locations!$C4))))),0) -> 5192
A5: =Locations!A5 -> Ambrose | B5: =ROUND(3958.8*5280*ACOS(MIN(1,MAX(-1,SIN(RADIANS(Locations!$B5))*SIN(RADIANS(Locations!$B2))+COS(RADIANS(Locations!$B5))*COS(RADIANS(Locations!$B2))*COS(RADIANS(Locations!$C2-Locations!$C5))))),0) -> 832 | C5: =ROUND(3958.8*5280*ACOS(MIN(1,MAX(-1,SIN(RADIANS(Locations!$B5))*SIN(RADIANS(Locations!$B3))+COS(RADIANS(Locations!$B5))*COS(RADIANS(Locations!$B3))*COS(RADIANS(Locations!$C3-Locations!$C5))))),0) -> 489 | D5: =ROUND(3958.8*5280*ACOS(MIN(1,MAX(-1,SIN(RADIANS(Locations!$B5))*SIN(RADIANS(Locations!$B4))+COS(RADIANS(Locations!$B5))*COS(RADIANS(Locations!$B4))*COS(RADIANS(Locations!$C4-Locations!$C5))))),0) -> 951 | E5: =0 -> 0 | F5: =ROUND(3958.8*5280*ACOS(MIN(1,MAX(-1,SIN(RADIANS(Locations!$B5))*SIN(RADIANS(Locations!$B6))+COS(RADIANS(Locations!$B5))*COS(RADIANS(Locations!$B6))*COS(RADIANS(Locations!$C6-Locations!$C5))))),0) -> 1016 | G5: =ROUND(3958.8*5280*ACOS(MIN(1,MAX(-1,SIN(RADIANS(Locations!$B5))*SIN(RADIANS(Locations!$B7))+COS(RADIANS(Locations!$B5))*COS(RADIANS(Locations!$B7))*COS(RADIANS(Locations!$C7-Locations!$C5))))),0) -> 1554 | H5: =ROUND(3958.8*5280*ACOS(MIN(1,MAX(-1,SIN(RADIANS(Locations!$B5))*SIN(RADIANS(Locations!$B8))+COS(RADIANS(Locations!$B5))*COS(RADIANS(Locations!$B8))*COS(RADIANS(Locations!$C8-Locations!$C5))))),0) -> 1601 | I5: =ROUND(3958.8*5280*ACOS(MIN(1,MAX(-1,SIN(RADIANS(Locations!$B5))*SIN(RADIANS(Locations!$B9))+COS(RADIANS(Locations!$B5))*COS(RADIANS(Locations!$B9))*COS(RADIANS(Locations!$C9-Locations!$C5))))),0) -> 1017 | J5: =ROUND(3958.8*5280*ACOS(MIN(1,MAX(-1,SIN(RADIANS(Locations!$B5))*SIN(RADIANS(Locations!$B10))+COS(RADIANS(Locations!$B5))*COS(RADIANS(Locations!$B10))*COS(RADIANS(Locations!$C10-Locations!$C5))))),0) -> 740 | K5: =ROUND(3958.8*5280*ACOS(MIN(1,MAX(-1,SIN(RADIANS(Locations!$B5))*SIN(RADIANS(Locations!$B11))+COS(RADIANS(Locations!$B5))*COS(RADIANS(Locations!$B11))*COS(RADIANS(Locations!$C11-Locations!$C5))))),0) -> 2932 | L5: =ROUND(3958.8*5280*ACOS(MIN(1,MAX(-1,SIN(RADIANS(Locations!$B5))*SIN(RADIANS(Locations!$B12))+COS(RADIANS(Locations!$B5))*COS(RADIANS(Locations!$B12))*COS(RADIANS(Locations!$C12-Locations!$C5))))),0) -> 3033 | M5: =ROUND(3958.8*5280*ACOS(MIN(1,MAX(-1,SIN(RADIANS(Locations!$B5))*SIN(RADIANS(Locations!$B13))+COS(RADIANS(Locations!$B5))*COS(RADIANS(Locations!$B13))*COS(RADIANS(Locations!$C13-Locations!$C5))))),0) -> 1986 | N5: =ROUND(3958.8*5280*ACOS(MIN(1,MAX(-1,SIN(RADIANS(Locations!$B5))*SIN(RADIANS(Locations!$B14))+COS(RADIANS(Locations!$B5))*COS(RADIANS(Locations!$B14))*COS(RADIANS(Locations!$C14-Locations!$C5))))),0) -> 3484 | O5: =ROUND(3958.8*5280*ACOS(MIN(1,MAX(-1,SIN(RADIANS(Locations!$B5))*SIN(RADIANS(Locations!$B15))+COS(RADIANS(Locations!$B5))*COS(RADIANS(Locations!$B15))*COS(RADIANS(Locations!$C15-Locations!$C5))))),0) -> 2917 | P5: =ROUND(3958.8*5280*ACOS(MIN(1,MAX(-1,SIN(RADIANS(Locations!$B5))*SIN(RADIANS(Locations!$B16))+COS(RADIANS(Locations!$B5))*COS(RADIANS(Locations!$B16))*COS(RADIANS(Locations!$C16-Locations!$C5))))),0) -> 2651 | Q5: =ROUND(3958.8*5280*ACOS(MIN(1,MAX(-1,SIN(RADIANS(Locations!$B5))*SIN(RADIANS(Locations!$B17))+COS(RADIANS(Locations!$B5))*COS(RADIANS(Locations!$B17))*COS(RADIANS(Locations!$C17-Locations!$C5))))),0) -> 2938 | R5: =ROUND(3958.8*5280*ACOS(MIN(1,MAX(-1,SIN(RADIANS(Locations!$B5))*SIN(RADIANS(Locations!$B18))+COS(RADIANS(Locations!$B5))*COS(RADIANS(Locations!$B18))*COS(RADIANS(Locations!$C18-Locations!$C5))))),0) -> 4247 | S5: =ROUND(3958.8*5280*ACOS(MIN(1,MAX(-1,SIN(RADIANS(Locations!$B5))*SIN(RADIANS(Locations!$B19))+COS(RADIANS(Locations!$B5))*COS(RADIANS(Locations!$B19))*COS(RADIANS(Locations!$C19-Locations!$C5))))),0) -> 4781 | T5: =ROUND(3958.8*5280*ACOS(MIN(1,MAX(-1,SIN(RADIANS(Locations!$B5))*SIN(RADIANS(Locations!$B20))+COS(RADIANS(Locations!$B5))*COS(RADIANS(Locations!$B20))*COS(RADIANS(Locations!$C20-Locations!$C5))))),0) -> 4380
A6: =Locations!A6 -> Dartmouth Court | B6: =ROUND(3958.8*5280*ACOS(MIN(1,MAX(-1,SIN(RADIANS(Locations!$B6))*SIN(RADIANS(Locations!$B2))+COS(RADIANS(Locations!$B6))*COS(RADIANS(Locations!$B2))*COS(RADIANS(Locations!$C2-Locations!$C6))))),0) -> 220 | C6: =ROUND(3958.8*5280*ACOS(MIN(1,MAX(-1,SIN(RADIANS(Locations!$B6))*SIN(RADIANS(Locations!$B3))+COS(RADIANS(Locations!$B6))*COS(RADIANS(Locations!$B3))*COS(RADIANS(Locations!$C3-Locations!$C6))))),0) -> 538 | D6: =ROUND(3958.8*5280*ACOS(MIN(1,MAX(-1,SIN(RADIANS(Locations!$B6))*SIN(RADIANS(Locations!$B4))+COS(RADIANS(Locations!$B6))*COS(RADIANS(Locations!$B4))*COS(RADIANS(Locations!$C4-Locations!$C6))))),0) -> 765 | E6: =ROUND(3958.8*5280*ACOS(MIN(1,MAX(-1,SIN(RADIANS(Locations!$B6))*SIN(RADIANS(Locations!$B5))+COS(RADIANS(Locations!$B6))*COS(RADIANS(Locations!$B5))*COS(RADIANS(Locations!$C5-Locations!$C6))))),0) -> 1016 | F6: =0 -> 0 | G6: =ROUND(3958.8*5280*ACOS(MIN(1,MAX(-1,SIN(RADIANS(Locations!$B6))*SIN(RADIANS(Locations!$B7))+COS(RADIANS(Locations!$B6))*COS(RADIANS(Locations!$B7))*COS(RADIANS(Locations!$C7-Locations!$C6))))),0) -> 730 | H6: =ROUND(3958.8*5280*ACOS(MIN(1,MAX(-1,SIN(RADIANS(Locations!$B6))*SIN(RADIANS(Locations!$B8))+COS(RADIANS(Locations!$B6))*COS(RADIANS(Locations!$B8))*COS(RADIANS(Locations!$C8-Locations!$C6))))),0) -> 916 | I6: =ROUND(3958.8*5280*ACOS(MIN(1,MAX(-1,SIN(RADIANS(Locations!$B6))*SIN(RADIANS(Locations!$B9))+COS(RADIANS(Locations!$B6))*COS(RADIANS(Locations!$B9))*COS(RADIANS(Locations!$C9-Locations!$C6))))),0) -> 1074 | J6: =ROUND(3958.8*5280*ACOS(MIN(1,MAX(-1,SIN(RADIANS(Locations!$B6))*SIN(RADIANS(Locations!$B10))+COS(RADIANS(Locations!$B6))*COS(RADIANS(Locations!$B10))*COS(RADIANS(Locations!$C10-Locations!$C6))))),0) -> 714 | K6: =ROUND(3958.8*5280*ACOS(MIN(1,MAX(-1,SIN(RADIANS(Locations!$B6))*SIN(RADIANS(Locations!$B11))+COS(RADIANS(Locations!$B6))*COS(RADIANS(Locations!$B11))*COS(RADIANS(Locations!$C11-Locations!$C6))))),0) -> 2097 | L6: =ROUND(3958.8*5280*ACOS(MIN(1,MAX(-1,SIN(RADIANS(Locations!$B6))*SIN(RADIANS(Locations!$B12))+COS(RADIANS(Locations!$B6))*COS(RADIANS(Locations!$B12))*COS(RADIANS(Locations!$C12-Locations!$C6))))),0) -> 2384 | M6: =ROUND(3958.8*5280*ACOS(MIN(1,MAX(-1,SIN(RADIANS(Locations!$B6))*SIN(RADIANS(Locations!$B13))+COS(RADIANS(Locations!$B6))*COS(RADIANS(Locations!$B13))*COS(RADIANS(Locations!$C13-Locations!$C6))))),0) -> 1950 | N6: =ROUND(3958.8*5280*ACOS(MIN(1,MAX(-1,SIN(RADIANS(Locations!$B6))*SIN(RADIANS(Locations!$B14))+COS(RADIANS(Locations!$B6))*COS(RADIANS(Locations!$B14))*COS(RADIANS(Locations!$C14-Locations!$C6))))),0) -> 3446 | O6: =ROUND(3958.8*5280*ACOS(MIN(1,MAX(-1,SIN(RADIANS(Locations!$B6))*SIN(RADIANS(Locations!$B15))+COS(RADIANS(Locations!$B6))*COS(RADIANS(Locations!$B15))*COS(RADIANS(Locations!$C15-Locations!$C6))))),0) -> 3153 | P6: =ROUND(3958.8*5280*ACOS(MIN(1,MAX(-1,SIN(RADIANS(Locations!$B6))*SIN(RADIANS(Locations!$B16))+COS(RADIANS(Locations!$B6))*COS(RADIANS(Locations!$B16))*COS(RADIANS(Locations!$C16-Locations!$C6))))),0) -> 2986 | Q6: =ROUND(3958.8*5280*ACOS(MIN(1,MAX(-1,SIN(RADIANS(Locations!$B6))*SIN(RADIANS(Locations!$B17))+COS(RADIANS(Locations!$B6))*COS(RADIANS(Locations!$B17))*COS(RADIANS(Locations!$C17-Locations!$C6))))),0) -> 3287 | R6: =ROUND(3958.8*5280*ACOS(MIN(1,MAX(-1,SIN(RADIANS(Locations!$B6))*SIN(RADIANS(Locations!$B18))+COS(RADIANS(Locations!$B6))*COS(RADIANS(Locations!$B18))*COS(RADIANS(Locations!$C18-Locations!$C6))))),0) -> 4706 | S6: =ROUND(3958.8*5280*ACOS(MIN(1,MAX(-1,SIN(RADIANS(Locations!$B6))*SIN(RADIANS(Locations!$B19))+COS(RADIANS(Locations!$B6))*COS(RADIANS(Locations!$B19))*COS(RADIANS(Locations!$C19-Locations!$C6))))),0) -> 5119 | T6: =ROUND(3958.8*5280*ACOS(MIN(1,MAX(-1,SIN(RADIANS(Locations!$B6))*SIN(RADIANS(Locations!$B20))+COS(RADIANS(Locations!$B6))*COS(RADIANS(Locations!$B20))*COS(RADIANS(Locations!$C20-Locations!$C6))))),0) -> 4664
A7: =Locations!A7 -> Columbia Court | B7: =ROUND(3958.8*5280*ACOS(MIN(1,MAX(-1,SIN(RADIANS(Locations!$B7))*SIN(RADIANS(Locations!$B2))+COS(RADIANS(Locations!$B7))*COS(RADIANS(Locations!$B2))*COS(RADIANS(Locations!$C2-Locations!$C7))))),0) -> 933 | C7: =ROUND(3958.8*5280*ACOS(MIN(1,MAX(-1,SIN(RADIANS(Locations!$B7))*SIN(RADIANS(Locations!$B3))+COS(RADIANS(Locations!$B7))*COS(RADIANS(Locations!$B3))*COS(RADIANS(Locations!$C3-Locations!$C7))))),0) -> 1163 | D7: =ROUND(3958.8*5280*ACOS(MIN(1,MAX(-1,SIN(RADIANS(Locations!$B7))*SIN(RADIANS(Locations!$B4))+COS(RADIANS(Locations!$B7))*COS(RADIANS(Locations!$B4))*COS(RADIANS(Locations!$C4-Locations!$C7))))),0) -> 1491 | E7: =ROUND(3958.8*5280*ACOS(MIN(1,MAX(-1,SIN(RADIANS(Locations!$B7))*SIN(RADIANS(Locations!$B5))+COS(RADIANS(Locations!$B7))*COS(RADIANS(Locations!$B5))*COS(RADIANS(Locations!$C5-Locations!$C7))))),0) -> 1554 | F7: =ROUND(3958.8*5280*ACOS(MIN(1,MAX(-1,SIN(RADIANS(Locations!$B7))*SIN(RADIANS(Locations!$B6))+COS(RADIANS(Locations!$B7))*COS(RADIANS(Locations!$B6))*COS(RADIANS(Locations!$C6-Locations!$C7))))),0) -> 730 | G7: =0 -> 0 | H7: =ROUND(3958.8*5280*ACOS(MIN(1,MAX(-1,SIN(RADIANS(Locations!$B7))*SIN(RADIANS(Locations!$B8))+COS(RADIANS(Locations!$B7))*COS(RADIANS(Locations!$B8))*COS(RADIANS(Locations!$C8-Locations!$C7))))),0) -> 265 | I7: =ROUND(3958.8*5280*ACOS(MIN(1,MAX(-1,SIN(RADIANS(Locations!$B7))*SIN(RADIANS(Locations!$B9))+COS(RADIANS(Locations!$B7))*COS(RADIANS(Locations!$B9))*COS(RADIANS(Locations!$C9-Locations!$C7))))),0) -> 1033 | J7: =ROUND(3958.8*5280*ACOS(MIN(1,MAX(-1,SIN(RADIANS(Locations!$B7))*SIN(RADIANS(Locations!$B10))+COS(RADIANS(Locations!$B7))*COS(RADIANS(Locations!$B10))*COS(RADIANS(Locations!$C10-Locations!$C7))))),0) -> 910 | K7: =ROUND(3958.8*5280*ACOS(MIN(1,MAX(-1,SIN(RADIANS(Locations!$B7))*SIN(RADIANS(Locations!$B11))+COS(RADIANS(Locations!$B7))*COS(RADIANS(Locations!$B11))*COS(RADIANS(Locations!$C11-Locations!$C7))))),0) -> 2304 | L7: =ROUND(3958.8*5280*ACOS(MIN(1,MAX(-1,SIN(RADIANS(Locations!$B7))*SIN(RADIANS(Locations!$B12))+COS(RADIANS(Locations!$B7))*COS(RADIANS(Locations!$B12))*COS(RADIANS(Locations!$C12-Locations!$C7))))),0) -> 1657 | M7: =ROUND(3958.8*5280*ACOS(MIN(1,MAX(-1,SIN(RADIANS(Locations!$B7))*SIN(RADIANS(Locations!$B13))+COS(RADIANS(Locations!$B7))*COS(RADIANS(Locations!$B13))*COS(RADIANS(Locations!$C13-Locations!$C7))))),0) -> 1558 | N7: =ROUND(3958.8*5280*ACOS(MIN(1,MAX(-1,SIN(RADIANS(Locations!$B7))*SIN(RADIANS(Locations!$B14))+COS(RADIANS(Locations!$B7))*COS(RADIANS(Locations!$B14))*COS(RADIANS(Locations!$C14-Locations!$C7))))),0) -> 2936 | O7: =ROUND(3958.8*5280*ACOS(MIN(1,MAX(-1,SIN(RADIANS(Locations!$B7))*SIN(RADIANS(Locations!$B15))+COS(RADIANS(Locations!$B7))*COS(RADIANS(Locations!$B15))*COS(RADIANS(Locations!$C15-Locations!$C7))))),0) -> 2829 | P7: =ROUND(3958.8*5280*ACOS(MIN(1,MAX(-1,SIN(RADIANS(Locations!$B7))*SIN(RADIANS(Locations!$B16))+COS(RADIANS(Locations!$B7))*COS(RADIANS(Locations!$B16))*COS(RADIANS(Locations!$C16-Locations!$C7))))),0) -> 2742 | Q7: =ROUND(3958.8*5280*ACOS(MIN(1,MAX(-1,SIN(RADIANS(Locations!$B7))*SIN(RADIANS(Locations!$B17))+COS(RADIANS(Locations!$B7))*COS(RADIANS(Locations!$B17))*COS(RADIANS(Locations!$C17-Locations!$C7))))),0) -> 3035 | R7: =ROUND(3958.8*5280*ACOS(MIN(1,MAX(-1,SIN(RADIANS(Locations!$B7))*SIN(RADIANS(Locations!$B18))+COS(RADIANS(Locations!$B7))*COS(RADIANS(Locations!$B18))*COS(RADIANS(Locations!$C18-Locations!$C7))))),0) -> 4477 | S7: =ROUND(3958.8*5280*ACOS(MIN(1,MAX(-1,SIN(RADIANS(Locations!$B7))*SIN(RADIANS(Locations!$B19))+COS(RADIANS(Locations!$B7))*COS(RADIANS(Locations!$B19))*COS(RADIANS(Locations!$C19-Locations!$C7))))),0) -> 4795 | T7: =ROUND(3958.8*5280*ACOS(MIN(1,MAX(-1,SIN(RADIANS(Locations!$B7))*SIN(RADIANS(Locations!$B20))+COS(RADIANS(Locations!$B7))*COS(RADIANS(Locations!$B20))*COS(RADIANS(Locations!$C20-Locations!$C7))))),0) -> 4314
A8: =Locations!A8 -> Berkeley Court | B8: =ROUND(3958.8*5280*ACOS(MIN(1,MAX(-1,SIN(RADIANS(Locations!$B8))*SIN(RADIANS(Locations!$B2))+COS(RADIANS(Locations!$B8))*COS(RADIANS(Locations!$B2))*COS(RADIANS(Locations!$C2-Locations!$C8))))),0) -> 1096 | C8: =ROUND(3958.8*5280*ACOS(MIN(1,MAX(-1,SIN(RADIANS(Locations!$B8))*SIN(RADIANS(Locations!$B3))+COS(RADIANS(Locations!$B8))*COS(RADIANS(Locations!$B3))*COS(RADIANS(Locations!$C3-Locations!$C8))))),0) -> 1271 | D8: =ROUND(3958.8*5280*ACOS(MIN(1,MAX(-1,SIN(RADIANS(Locations!$B8))*SIN(RADIANS(Locations!$B4))+COS(RADIANS(Locations!$B8))*COS(RADIANS(Locations!$B4))*COS(RADIANS(Locations!$C4-Locations!$C8))))),0) -> 1679 | E8: =ROUND(3958.8*5280*ACOS(MIN(1,MAX(-1,SIN(RADIANS(Locations!$B8))*SIN(RADIANS(Locations!$B5))+COS(RADIANS(Locations!$B8))*COS(RADIANS(Locations!$B5))*COS(RADIANS(Locations!$C5-Locations!$C8))))),0) -> 1601 | F8: =ROUND(3958.8*5280*ACOS(MIN(1,MAX(-1,SIN(RADIANS(Locations!$B8))*SIN(RADIANS(Locations!$B6))+COS(RADIANS(Locations!$B8))*COS(RADIANS(Locations!$B6))*COS(RADIANS(Locations!$C6-Locations!$C8))))),0) -> 916 | G8: =ROUND(3958.8*5280*ACOS(MIN(1,MAX(-1,SIN(RADIANS(Locations!$B8))*SIN(RADIANS(Locations!$B7))+COS(RADIANS(Locations!$B8))*COS(RADIANS(Locations!$B7))*COS(RADIANS(Locations!$C7-Locations!$C8))))),0) -> 265 | H8: =0 -> 0 | I8: =ROUND(3958.8*5280*ACOS(MIN(1,MAX(-1,SIN(RADIANS(Locations!$B8))*SIN(RADIANS(Locations!$B9))+COS(RADIANS(Locations!$B8))*COS(RADIANS(Locations!$B9))*COS(RADIANS(Locations!$C9-Locations!$C8))))),0) -> 909 | J8: =ROUND(3958.8*5280*ACOS(MIN(1,MAX(-1,SIN(RADIANS(Locations!$B8))*SIN(RADIANS(Locations!$B10))+COS(RADIANS(Locations!$B8))*COS(RADIANS(Locations!$B10))*COS(RADIANS(Locations!$C10-Locations!$C8))))),0) -> 893 | K8: =ROUND(3958.8*5280*ACOS(MIN(1,MAX(-1,SIN(RADIANS(Locations!$B8))*SIN(RADIANS(Locations!$B11))+COS(RADIANS(Locations!$B8))*COS(RADIANS(Locations!$B11))*COS(RADIANS(Locations!$C11-Locations!$C8))))),0) -> 2563 | L8: =ROUND(3958.8*5280*ACOS(MIN(1,MAX(-1,SIN(RADIANS(Locations!$B8))*SIN(RADIANS(Locations!$B12))+COS(RADIANS(Locations!$B8))*COS(RADIANS(Locations!$B12))*COS(RADIANS(Locations!$C12-Locations!$C8))))),0) -> 1486 | M8: =ROUND(3958.8*5280*ACOS(MIN(1,MAX(-1,SIN(RADIANS(Locations!$B8))*SIN(RADIANS(Locations!$B13))+COS(RADIANS(Locations!$B8))*COS(RADIANS(Locations!$B13))*COS(RADIANS(Locations!$C13-Locations!$C8))))),0) -> 1306 | N8: =ROUND(3958.8*5280*ACOS(MIN(1,MAX(-1,SIN(RADIANS(Locations!$B8))*SIN(RADIANS(Locations!$B14))+COS(RADIANS(Locations!$B8))*COS(RADIANS(Locations!$B14))*COS(RADIANS(Locations!$C14-Locations!$C8))))),0) -> 2672 | O8: =ROUND(3958.8*5280*ACOS(MIN(1,MAX(-1,SIN(RADIANS(Locations!$B8))*SIN(RADIANS(Locations!$B15))+COS(RADIANS(Locations!$B8))*COS(RADIANS(Locations!$B15))*COS(RADIANS(Locations!$C15-Locations!$C8))))),0) -> 2578 | P8: =ROUND(3958.8*5280*ACOS(MIN(1,MAX(-1,SIN(RADIANS(Locations!$B8))*SIN(RADIANS(Locations!$B16))+COS(RADIANS(Locations!$B8))*COS(RADIANS(Locations!$B16))*COS(RADIANS(Locations!$C16-Locations!$C8))))),0) -> 2505 | Q8: =ROUND(3958.8*5280*ACOS(MIN(1,MAX(-1,SIN(RADIANS(Locations!$B8))*SIN(RADIANS(Locations!$B17))+COS(RADIANS(Locations!$B8))*COS(RADIANS(Locations!$B17))*COS(RADIANS(Locations!$C17-Locations!$C8))))),0) -> 2795 | R8: =ROUND(3958.8*5280*ACOS(MIN(1,MAX(-1,SIN(RADIANS(Locations!$B8))*SIN(RADIANS(Locations!$B18))+COS(RADIANS(Locations!$B8))*COS(RADIANS(Locations!$B18))*COS(RADIANS(Locations!$C18-Locations!$C8))))),0) -> 4237 | S8: =ROUND(3958.8*5280*ACOS(MIN(1,MAX(-1,SIN(RADIANS(Locations!$B8))*SIN(RADIANS(Locations!$B19))+COS(RADIANS(Locations!$B8))*COS(RADIANS(Locations!$B19))*COS(RADIANS(Locations!$C19-Locations!$C8))))),0) -> 4540 | T8: =ROUND(3958.8*5280*ACOS(MIN(1,MAX(-1,SIN(RADIANS(Locations!$B8))*SIN(RADIANS(Locations!$B20))+COS(RADIANS(Locations!$B8))*COS(RADIANS(Locations!$B20))*COS(RADIANS(Locations!$C20-Locations!$C8))))),0) -> 4057
A9: =Locations!A9 -> Harvard Court | B9: =ROUND(3958.8*5280*ACOS(MIN(1,MAX(-1,SIN(RADIANS(Locations!$B9))*SIN(RADIANS(Locations!$B2))+COS(RADIANS(Locations!$B9))*COS(RADIANS(Locations!$B2))*COS(RADIANS(Locations!$C2-Locations!$C9))))),0) -> 1087 | C9: =ROUND(3958.8*5280*ACOS(MIN(1,MAX(-1,SIN(RADIANS(Locations!$B9))*SIN(RADIANS(Locations!$B3))+COS(RADIANS(Locations!$B9))*COS(RADIANS(Locations!$B3))*COS(RADIANS(Locations!$C3-Locations!$C9))))),0) -> 986 | D9: =ROUND(3958.8*5280*ACOS(MIN(1,MAX(-1,SIN(RADIANS(Locations!$B9))*SIN(RADIANS(Locations!$B4))+COS(RADIANS(Locations!$B9))*COS(RADIANS(Locations!$B4))*COS(RADIANS(Locations!$C4-Locations!$C9))))),0) -> 1606 | E9: =ROUND(3958.8*5280*ACOS(MIN(1,MAX(-1,SIN(RADIANS(Locations!$B9))*SIN(RADIANS(Locations!$B5))+COS(RADIANS(Locations!$B9))*COS(RADIANS(Locations!$B5))*COS(RADIANS(Locations!$C5-Locations!$C9))))),0) -> 1017 | F9: =ROUND(3958.8*5280*ACOS(MIN(1,MAX(-1,SIN(RADIANS(Locations!$B9))*SIN(RADIANS(Locations!$B6))+COS(RADIANS(Locations!$B9))*COS(RADIANS(Locations!$B6))*COS(RADIANS(Locations!$C6-Locations!$C9))))),0) -> 1074 | G9: =ROUND(3958.8*5280*ACOS(MIN(1,MAX(-1,SIN(RADIANS(Locations!$B9))*SIN(RADIANS(Locations!$B7))+COS(RADIANS(Locations!$B9))*COS(RADIANS(Locations!$B7))*COS(RADIANS(Locations!$C7-Locations!$C9))))),0) -> 1033 | H9: =ROUND(3958.8*5280*ACOS(MIN(1,MAX(-1,SIN(RADIANS(Locations!$B9))*SIN(RADIANS(Locations!$B8))+COS(RADIANS(Locations!$B9))*COS(RADIANS(Locations!$B8))*COS(RADIANS(Locations!$C8-Locations!$C9))))),0) -> 909 | I9: =0 -> 0 | J9: =ROUND(3958.8*5280*ACOS(MIN(1,MAX(-1,SIN(RADIANS(Locations!$B9))*SIN(RADIANS(Locations!$B10))+COS(RADIANS(Locations!$B9))*COS(RADIANS(Locations!$B10))*COS(RADIANS(Locations!$C10-Locations!$C9))))),0) -> 400 | K9: =ROUND(3958.8*5280*ACOS(MIN(1,MAX(-1,SIN(RADIANS(Locations!$B9))*SIN(RADIANS(Locations!$B11))+COS(RADIANS(Locations!$B9))*COS(RADIANS(Locations!$B11))*COS(RADIANS(Locations!$C11-Locations!$C9))))),0) -> 3143 | L9: =ROUND(3958.8*5280*ACOS(MIN(1,MAX(-1,SIN(RADIANS(Locations!$B9))*SIN(RADIANS(Locations!$B12))+COS(RADIANS(Locations!$B9))*COS(RADIANS(Locations!$B12))*COS(RADIANS(Locations!$C12-Locations!$C9))))),0) -> 2118 | M9: =ROUND(3958.8*5280*ACOS(MIN(1,MAX(-1,SIN(RADIANS(Locations!$B9))*SIN(RADIANS(Locations!$B13))+COS(RADIANS(Locations!$B9))*COS(RADIANS(Locations!$B13))*COS(RADIANS(Locations!$C13-Locations!$C9))))),0) -> 996 | N9: =ROUND(3958.8*5280*ACOS(MIN(1,MAX(-1,SIN(RADIANS(Locations!$B9))*SIN(RADIANS(Locations!$B14))+COS(RADIANS(Locations!$B9))*COS(RADIANS(Locations!$B14))*COS(RADIANS(Locations!$C14-Locations!$C9))))),0) -> 2520 | O9: =ROUND(3958.8*5280*ACOS(MIN(1,MAX(-1,SIN(RADIANS(Locations!$B9))*SIN(RADIANS(Locations!$B15))+COS(RADIANS(Locations!$B9))*COS(RADIANS(Locations!$B15))*COS(RADIANS(Locations!$C15-Locations!$C9))))),0) -> 2100 | P9: =ROUND(3958.8*5280*ACOS(MIN(1,MAX(-1,SIN(RADIANS(Locations!$B9))*SIN(RADIANS(Locations!$B16))+COS(RADIANS(Locations!$B9))*COS(RADIANS(Locations!$B16))*COS(RADIANS(Locations!$C16-Locations!$C9))))),0) -> 1914 | Q9: =ROUND(3958.8*5280*ACOS(MIN(1,MAX(-1,SIN(RADIANS(Locations!$B9))*SIN(RADIANS(Locations!$B17))+COS(RADIANS(Locations!$B9))*COS(RADIANS(Locations!$B17))*COS(RADIANS(Locations!$C17-Locations!$C9))))),0) -> 2216 | R9: =ROUND(3958.8*5280*ACOS(MIN(1,MAX(-1,SIN(RADIANS(Locations!$B9))*SIN(RADIANS(Locations!$B18))+COS(RADIANS(Locations!$B9))*COS(RADIANS(Locations!$B18))*COS(RADIANS(Locations!$C18-Locations!$C9))))),0) -> 3632 | S9: =ROUND(3958.8*5280*ACOS(MIN(1,MAX(-1,SIN(RADIANS(Locations!$B9))*SIN(RADIANS(Locations!$B19))+COS(RADIANS(Locations!$B9))*COS(RADIANS(Locations!$B19))*COS(RADIANS(Locations!$C19-Locations!$C9))))),0) -> 4055 | T9: =ROUND(3958.8*5280*ACOS(MIN(1,MAX(-1,SIN(RADIANS(Locations!$B9))*SIN(RADIANS(Locations!$B20))+COS(RADIANS(Locations!$B9))*COS(RADIANS(Locations!$B20))*COS(RADIANS(Locations!$C20-Locations!$C9))))),0) -> 3609
A10: =Locations!A10 -> Cornell Court | B10: =ROUND(3958.8*5280*ACOS(MIN(1,MAX(-1,SIN(RADIANS(Locations!$B10))*SIN(RADIANS(Locations!$B2))+COS(RADIANS(Locations!$B10))*COS(RADIANS(Locations!$B2))*COS(RADIANS(Locations!$C2-Locations!$C10))))),0) -> 694 | C10: =ROUND(3958.8*5280*ACOS(MIN(1,MAX(-1,SIN(RADIANS(Locations!$B10))*SIN(RADIANS(Locations!$B3))+COS(RADIANS(Locations!$B10))*COS(RADIANS(Locations!$B3))*COS(RADIANS(Locations!$C3-Locations!$C10))))),0) -> 594 | D10: =ROUND(3958.8*5280*ACOS(MIN(1,MAX(-1,SIN(RADIANS(Locations!$B10))*SIN(RADIANS(Locations!$B4))+COS(RADIANS(Locations!$B10))*COS(RADIANS(Locations!$B4))*COS(RADIANS(Locations!$C4-Locations!$C10))))),0) -> 1207 | E10: =ROUND(3958.8*5280*ACOS(MIN(1,MAX(-1,SIN(RADIANS(Locations!$B10))*SIN(RADIANS(Locations!$B5))+COS(RADIANS(Locations!$B10))*COS(RADIANS(Locations!$B5))*COS(RADIANS(Locations!$C5-Locations!$C10))))),0) -> 740 | F10: =ROUND(3958.8*5280*ACOS(MIN(1,MAX(-1,SIN(RADIANS(Locations!$B10))*SIN(RADIANS(Locations!$B6))+COS(RADIANS(Locations!$B10))*COS(RADIANS(Locations!$B6))*COS(RADIANS(Locations!$C6-Locations!$C10))))),0) -> 714 | G10: =ROUND(3958.8*5280*ACOS(MIN(1,MAX(-1,SIN(RADIANS(Locations!$B10))*SIN(RADIANS(Locations!$B7))+COS(RADIANS(Locations!$B10))*COS(RADIANS(Locations!$B7))*COS(RADIANS(Locations!$C7-Locations!$C10))))),0) -> 910 | H10: =ROUND(3958.8*5280*ACOS(MIN(1,MAX(-1,SIN(RADIANS(Locations!$B10))*SIN(RADIANS(Locations!$B8))+COS(RADIANS(Locations!$B10))*COS(RADIANS(Locations!$B8))*COS(RADIANS(Locations!$C8-Locations!$C10))))),0) -> 893 | I10: =ROUND(3958.8*5280*ACOS(MIN(1,MAX(-1,SIN(RADIANS(Locations!$B10))*SIN(RADIANS(Locations!$B9))+COS(RADIANS(Locations!$B10))*COS(RADIANS(Locations!$B9))*COS(RADIANS(Locations!$C9-Locations!$C10))))),0) -> 400 | J10: =0 -> 0 | K10: =ROUND(3958.8*5280*ACOS(MIN(1,MAX(-1,SIN(RADIANS(Locations!$B10))*SIN(RADIANS(Locations!$B11))+COS(RADIANS(Locations!$B10))*COS(RADIANS(Locations!$B11))*COS(RADIANS(Locations!$C11-Locations!$C10))))),0) -> 2808 | L10: =ROUND(3958.8*5280*ACOS(MIN(1,MAX(-1,SIN(RADIANS(Locations!$B10))*SIN(RADIANS(Locations!$B12))+COS(RADIANS(Locations!$B10))*COS(RADIANS(Locations!$B12))*COS(RADIANS(Locations!$C12-Locations!$C10))))),0) -> 2293 | M10: =ROUND(3958.8*5280*ACOS(MIN(1,MAX(-1,SIN(RADIANS(Locations!$B10))*SIN(RADIANS(Locations!$B13))+COS(RADIANS(Locations!$B10))*COS(RADIANS(Locations!$B13))*COS(RADIANS(Locations!$C13-Locations!$C10))))),0) -> 1381 | N10: =ROUND(3958.8*5280*ACOS(MIN(1,MAX(-1,SIN(RADIANS(Locations!$B10))*SIN(RADIANS(Locations!$B14))+COS(RADIANS(Locations!$B10))*COS(RADIANS(Locations!$B14))*COS(RADIANS(Locations!$C14-Locations!$C10))))),0) -> 2907 | O10: =ROUND(3958.8*5280*ACOS(MIN(1,MAX(-1,SIN(RADIANS(Locations!$B10))*SIN(RADIANS(Locations!$B15))+COS(RADIANS(Locations!$B10))*COS(RADIANS(Locations!$B15))*COS(RADIANS(Locations!$C15-Locations!$C10))))),0) -> 2498 | P10: =ROUND(3958.8*5280*ACOS(MIN(1,MAX(-1,SIN(RADIANS(Locations!$B10))*SIN(RADIANS(Locations!$B16))+COS(RADIANS(Locations!$B10))*COS(RADIANS(Locations!$B16))*COS(RADIANS(Locations!$C16-Locations!$C10))))),0) -> 2302 | Q10: =ROUND(3958.8*5280*ACOS(MIN(1,MAX(-1,SIN(RADIANS(Locations!$B10))*SIN(RADIANS(Locations!$B17))+COS(RADIANS(Locations!$B10))*COS(RADIANS(Locations!$B17))*COS(RADIANS(Locations!$C17-Locations!$C10))))),0) -> 2603 | R10: =ROUND(3958.8*5280*ACOS(MIN(1,MAX(-1,SIN(RADIANS(Locations!$B10))*SIN(RADIANS(Locations!$B18))+COS(RADIANS(Locations!$B10))*COS(RADIANS(Locations!$B18))*COS(RADIANS(Locations!$C18-Locations!$C10))))),0) -> 4007 | S10: =ROUND(3958.8*5280*ACOS(MIN(1,MAX(-1,SIN(RADIANS(Locations!$B10))*SIN(RADIANS(Locations!$B19))+COS(RADIANS(Locations!$B10))*COS(RADIANS(Locations!$B19))*COS(RADIANS(Locations!$C19-Locations!$C10))))),0) -> 4448 | T10: =ROUND(3958.8*5280*ACOS(MIN(1,MAX(-1,SIN(RADIANS(Locations!$B10))*SIN(RADIANS(Locations!$B20))+COS(RADIANS(Locations!$B10))*COS(RADIANS(Locations!$B20))*COS(RADIANS(Locations!$C20-Locations!$C10))))),0) -> 4006
A11: =Locations!A11 -> Mesa Court | B11: =ROUND(3958.8*5280*ACOS(MIN(1,MAX(-1,SIN(RADIANS(Locations!$B11))*SIN(RADIANS(Locations!$B2))+COS(RADIANS(Locations!$B11))*COS(RADIANS(Locations!$B2))*COS(RADIANS(Locations!$C2-Locations!$C11))))),0) -> 2177 | C11: =ROUND(3958.8*5280*ACOS(MIN(1,MAX(-1,SIN(RADIANS(Locations!$B11))*SIN(RADIANS(Locations!$B3))+COS(RADIANS(Locations!$B11))*COS(RADIANS(Locations!$B3))*COS(RADIANS(Locations!$C3-Locations!$C11))))),0) -> 2478 | D11: =ROUND(3958.8*5280*ACOS(MIN(1,MAX(-1,SIN(RADIANS(Locations!$B11))*SIN(RADIANS(Locations!$B4))+COS(RADIANS(Locations!$B11))*COS(RADIANS(Locations!$B4))*COS(RADIANS(Locations!$C4-Locations!$C11))))),0) -> 2041 | E11: =ROUND(3958.8*5280*ACOS(MIN(1,MAX(-1,SIN(RADIANS(Locations!$B11))*SIN(RADIANS(Locations!$B5))+COS(RADIANS(Locations!$B11))*COS(RADIANS(Locations!$B5))*COS(RADIANS(Locations!$C5-Locations!$C11))))),0) -> 2932 | F11: =ROUND(3958.8*5280*ACOS(MIN(1,MAX(-1,SIN(RADIANS(Locations!$B11))*SIN(RADIANS(Locations!$B6))+COS(RADIANS(Locations!$B11))*COS(RADIANS(Locations!$B6))*COS(RADIANS(Locations!$C6-Locations!$C11))))),0) -> 2097 | G11: =ROUND(3958.8*5280*ACOS(MIN(1,MAX(-1,SIN(RADIANS(Locations!$B11))*SIN(RADIANS(Locations!$B7))+COS(RADIANS(Locations!$B11))*COS(RADIANS(Locations!$B7))*COS(RADIANS(Locations!$C7-Locations!$C11))))),0) -> 2304 | H11: =ROUND(3958.8*5280*ACOS(MIN(1,MAX(-1,SIN(RADIANS(Locations!$B11))*SIN(RADIANS(Locations!$B8))+COS(RADIANS(Locations!$B11))*COS(RADIANS(Locations!$B8))*COS(RADIANS(Locations!$C8-Locations!$C11))))),0) -> 2563 | I11: =ROUND(3958.8*5280*ACOS(MIN(1,MAX(-1,SIN(RADIANS(Locations!$B11))*SIN(RADIANS(Locations!$B9))+COS(RADIANS(Locations!$B11))*COS(RADIANS(Locations!$B9))*COS(RADIANS(Locations!$C9-Locations!$C11))))),0) -> 3143 | J11: =ROUND(3958.8*5280*ACOS(MIN(1,MAX(-1,SIN(RADIANS(Locations!$B11))*SIN(RADIANS(Locations!$B10))+COS(RADIANS(Locations!$B11))*COS(RADIANS(Locations!$B10))*COS(RADIANS(Locations!$C10-Locations!$C11))))),0) -> 2808 | K11: =0 -> 0 | L11: =ROUND(3958.8*5280*ACOS(MIN(1,MAX(-1,SIN(RADIANS(Locations!$B11))*SIN(RADIANS(Locations!$B12))+COS(RADIANS(Locations!$B11))*COS(RADIANS(Locations!$B12))*COS(RADIANS(Locations!$C12-Locations!$C11))))),0) -> 3467 | M11: =ROUND(3958.8*5280*ACOS(MIN(1,MAX(-1,SIN(RADIANS(Locations!$B11))*SIN(RADIANS(Locations!$B13))+COS(RADIANS(Locations!$B11))*COS(RADIANS(Locations!$B13))*COS(RADIANS(Locations!$C13-Locations!$C11))))),0) -> 3859 | N11: =ROUND(3958.8*5280*ACOS(MIN(1,MAX(-1,SIN(RADIANS(Locations!$B11))*SIN(RADIANS(Locations!$B14))+COS(RADIANS(Locations!$B11))*COS(RADIANS(Locations!$B14))*COS(RADIANS(Locations!$C14-Locations!$C11))))),0) -> 5202 | O11: =ROUND(3958.8*5280*ACOS(MIN(1,MAX(-1,SIN(RADIANS(Locations!$B11))*SIN(RADIANS(Locations!$B15))+COS(RADIANS(Locations!$B11))*COS(RADIANS(Locations!$B15))*COS(RADIANS(Locations!$C15-Locations!$C11))))),0) -> 5126 | P11: =ROUND(3958.8*5280*ACOS(MIN(1,MAX(-1,SIN(RADIANS(Locations!$B11))*SIN(RADIANS(Locations!$B16))+COS(RADIANS(Locations!$B11))*COS(RADIANS(Locations!$B16))*COS(RADIANS(Locations!$C16-Locations!$C11))))),0) -> 5014 | Q11: =ROUND(3958.8*5280*ACOS(MIN(1,MAX(-1,SIN(RADIANS(Locations!$B11))*SIN(RADIANS(Locations!$B17))+COS(RADIANS(Locations!$B11))*COS(RADIANS(Locations!$B17))*COS(RADIANS(Locations!$C17-Locations!$C11))))),0) -> 5312 | R11: =ROUND(3958.8*5280*ACOS(MIN(1,MAX(-1,SIN(RADIANS(Locations!$B11))*SIN(RADIANS(Locations!$B18))+COS(RADIANS(Locations!$B11))*COS(RADIANS(Locations!$B18))*COS(RADIANS(Locations!$C18-Locations!$C11))))),0) -> 6750 | S11: =ROUND(3958.8*5280*ACOS(MIN(1,MAX(-1,SIN(RADIANS(Locations!$B11))*SIN(RADIANS(Locations!$B19))+COS(RADIANS(Locations!$B11))*COS(RADIANS(Locations!$B19))*COS(RADIANS(Locations!$C19-Locations!$C11))))),0) -> 7097 | T11: =ROUND(3958.8*5280*ACOS(MIN(1,MAX(-1,SIN(RADIANS(Locations!$B11))*SIN(RADIANS(Locations!$B20))+COS(RADIANS(Locations!$B11))*COS(RADIANS(Locations!$B20))*COS(RADIANS(Locations!$C20-Locations!$C11))))),0) -> 6617
A12: =Locations!A12 -> Middle Earth | B12: =ROUND(3958.8*5280*ACOS(MIN(1,MAX(-1,SIN(RADIANS(Locations!$B12))*SIN(RADIANS(Locations!$B2))+COS(RADIANS(Locations!$B12))*COS(RADIANS(Locations!$B2))*COS(RADIANS(Locations!$C2-Locations!$C12))))),0) -> 2577 | C12: =ROUND(3958.8*5280*ACOS(MIN(1,MAX(-1,SIN(RADIANS(Locations!$B12))*SIN(RADIANS(Locations!$B3))+COS(RADIANS(Locations!$B12))*COS(RADIANS(Locations!$B3))*COS(RADIANS(Locations!$C3-Locations!$C12))))),0) -> 2752 | D12: =ROUND(3958.8*5280*ACOS(MIN(1,MAX(-1,SIN(RADIANS(Locations!$B12))*SIN(RADIANS(Locations!$B4))+COS(RADIANS(Locations!$B12))*COS(RADIANS(Locations!$B4))*COS(RADIANS(Locations!$C4-Locations!$C12))))),0) -> 3147 | E12: =ROUND(3958.8*5280*ACOS(MIN(1,MAX(-1,SIN(RADIANS(Locations!$B12))*SIN(RADIANS(Locations!$B5))+COS(RADIANS(Locations!$B12))*COS(RADIANS(Locations!$B5))*COS(RADIANS(Locations!$C5-Locations!$C12))))),0) -> 3033 | F12: =ROUND(3958.8*5280*ACOS(MIN(1,MAX(-1,SIN(RADIANS(Locations!$B12))*SIN(RADIANS(Locations!$B6))+COS(RADIANS(Locations!$B12))*COS(RADIANS(Locations!$B6))*COS(RADIANS(Locations!$C6-Locations!$C12))))),0) -> 2384 | G12: =ROUND(3958.8*5280*ACOS(MIN(1,MAX(-1,SIN(RADIANS(Locations!$B12))*SIN(RADIANS(Locations!$B7))+COS(RADIANS(Locations!$B12))*COS(RADIANS(Locations!$B7))*COS(RADIANS(Locations!$C7-Locations!$C12))))),0) -> 1657 | H12: =ROUND(3958.8*5280*ACOS(MIN(1,MAX(-1,SIN(RADIANS(Locations!$B12))*SIN(RADIANS(Locations!$B8))+COS(RADIANS(Locations!$B12))*COS(RADIANS(Locations!$B8))*COS(RADIANS(Locations!$C8-Locations!$C12))))),0) -> 1486 | I12: =ROUND(3958.8*5280*ACOS(MIN(1,MAX(-1,SIN(RADIANS(Locations!$B12))*SIN(RADIANS(Locations!$B9))+COS(RADIANS(Locations!$B12))*COS(RADIANS(Locations!$B9))*COS(RADIANS(Locations!$C9-Locations!$C12))))),0) -> 2118 | J12: =ROUND(3958.8*5280*ACOS(MIN(1,MAX(-1,SIN(RADIANS(Locations!$B12))*SIN(RADIANS(Locations!$B10))+COS(RADIANS(Locations!$B12))*COS(RADIANS(Locations!$B10))*COS(RADIANS(Locations!$C10-Locations!$C12))))),0) -> 2293 | K12: =ROUND(3958.8*5280*ACOS(MIN(1,MAX(-1,SIN(RADIANS(Locations!$B12))*SIN(RADIANS(Locations!$B11))+COS(RADIANS(Locations!$B12))*COS(RADIANS(Locations!$B11))*COS(RADIANS(Locations!$C11-Locations!$C12))))),0) -> 3467 | L12: =0 -> 0 | M12: =ROUND(3958.8*5280*ACOS(MIN(1,MAX(-1,SIN(RADIANS(Locations!$B12))*SIN(RADIANS(Locations!$B13))+COS(RADIANS(Locations!$B12))*COS(RADIANS(Locations!$B13))*COS(RADIANS(Locations!$C13-Locations!$C12))))),0) -> 1666 | N12: =ROUND(3958.8*5280*ACOS(MIN(1,MAX(-1,SIN(RADIANS(Locations!$B12))*SIN(RADIANS(Locations!$B14))+COS(RADIANS(Locations!$B12))*COS(RADIANS(Locations!$B14))*COS(RADIANS(Locations!$C14-Locations!$C12))))),0) -> 2110 | O12: =ROUND(3958.8*5280*ACOS(MIN(1,MAX(-1,SIN(RADIANS(Locations!$B12))*SIN(RADIANS(Locations!$B15))+COS(RADIANS(Locations!$B12))*COS(RADIANS(Locations!$B15))*COS(RADIANS(Locations!$C15-Locations!$C12))))),0) -> 2581 | P12: =ROUND(3958.8*5280*ACOS(MIN(1,MAX(-1,SIN(RADIANS(Locations!$B12))*SIN(RADIANS(Locations!$B16))+COS(RADIANS(Locations!$B12))*COS(RADIANS(Locations!$B16))*COS(RADIANS(Locations!$C16-Locations!$C12))))),0) -> 2719 | Q12: =ROUND(3958.8*5280*ACOS(MIN(1,MAX(-1,SIN(RADIANS(Locations!$B12))*SIN(RADIANS(Locations!$B17))+COS(RADIANS(Locations!$B12))*COS(RADIANS(Locations!$B17))*COS(RADIANS(Locations!$C17-Locations!$C12))))),0) -> 2923 | R12: =ROUND(3958.8*5280*ACOS(MIN(1,MAX(-1,SIN(RADIANS(Locations!$B12))*SIN(RADIANS(Locations!$B18))+COS(RADIANS(Locations!$B12))*COS(RADIANS(Locations!$B18))*COS(RADIANS(Locations!$C18-Locations!$C12))))),0) -> 4214 | S12: =ROUND(3958.8*5280*ACOS(MIN(1,MAX(-1,SIN(RADIANS(Locations!$B12))*SIN(RADIANS(Locations!$B19))+COS(RADIANS(Locations!$B12))*COS(RADIANS(Locations!$B19))*COS(RADIANS(Locations!$C19-Locations!$C12))))),0) -> 4261 | T12: =ROUND(3958.8*5280*ACOS(MIN(1,MAX(-1,SIN(RADIANS(Locations!$B12))*SIN(RADIANS(Locations!$B20))+COS(RADIANS(Locations!$B12))*COS(RADIANS(Locations!$B20))*COS(RADIANS(Locations!$C20-Locations!$C12))))),0) -> 3757
A13: =Locations!A13 -> Puerta del Sol | B13: =ROUND(3958.8*5280*ACOS(MIN(1,MAX(-1,SIN(RADIANS(Locations!$B13))*SIN(RADIANS(Locations!$B2))+COS(RADIANS(Locations!$B13))*COS(RADIANS(Locations!$B2))*COS(RADIANS(Locations!$C2-Locations!$C13))))),0) -> 2022 | C13: =ROUND(3958.8*5280*ACOS(MIN(1,MAX(-1,SIN(RADIANS(Locations!$B13))*SIN(RADIANS(Locations!$B3))+COS(RADIANS(Locations!$B13))*COS(RADIANS(Locations!$B3))*COS(RADIANS(Locations!$C3-Locations!$C13))))),0) -> 1975 | D13: =ROUND(3958.8*5280*ACOS(MIN(1,MAX(-1,SIN(RADIANS(Locations!$B13))*SIN(RADIANS(Locations!$B4))+COS(RADIANS(Locations!$B13))*COS(RADIANS(Locations!$B4))*COS(RADIANS(Locations!$C4-Locations!$C13))))),0) -> 2581 | E13: =ROUND(3958.8*5280*ACOS(MIN(1,MAX(-1,SIN(RADIANS(Locations!$B13))*SIN(RADIANS(Locations!$B5))+COS(RADIANS(Locations!$B13))*COS(RADIANS(Locations!$B5))*COS(RADIANS(Locations!$C5-Locations!$C13))))),0) -> 1986 | F13: =ROUND(3958.8*5280*ACOS(MIN(1,MAX(-1,SIN(RADIANS(Locations!$B13))*SIN(RADIANS(Locations!$B6))+COS(RADIANS(Locations!$B13))*COS(RADIANS(Locations!$B6))*COS(RADIANS(Locations!$C6-Locations!$C13))))),0) -> 1950 | G13: =ROUND(3958.8*5280*ACOS(MIN(1,MAX(-1,SIN(RADIANS(Locations!$B13))*SIN(RADIANS(Locations!$B7))+COS(RADIANS(Locations!$B13))*COS(RADIANS(Locations!$B7))*COS(RADIANS(Locations!$C7-Locations!$C13))))),0) -> 1558 | H13: =ROUND(3958.8*5280*ACOS(MIN(1,MAX(-1,SIN(RADIANS(Locations!$B13))*SIN(RADIANS(Locations!$B8))+COS(RADIANS(Locations!$B13))*COS(RADIANS(Locations!$B8))*COS(RADIANS(Locations!$C8-Locations!$C13))))),0) -> 1306 | I13: =ROUND(3958.8*5280*ACOS(MIN(1,MAX(-1,SIN(RADIANS(Locations!$B13))*SIN(RADIANS(Locations!$B9))+COS(RADIANS(Locations!$B13))*COS(RADIANS(Locations!$B9))*COS(RADIANS(Locations!$C9-Locations!$C13))))),0) -> 996 | J13: =ROUND(3958.8*5280*ACOS(MIN(1,MAX(-1,SIN(RADIANS(Locations!$B13))*SIN(RADIANS(Locations!$B10))+COS(RADIANS(Locations!$B13))*COS(RADIANS(Locations!$B10))*COS(RADIANS(Locations!$C10-Locations!$C13))))),0) -> 1381 | K13: =ROUND(3958.8*5280*ACOS(MIN(1,MAX(-1,SIN(RADIANS(Locations!$B13))*SIN(RADIANS(Locations!$B11))+COS(RADIANS(Locations!$B13))*COS(RADIANS(Locations!$B11))*COS(RADIANS(Locations!$C11-Locations!$C13))))),0) -> 3859 | L13: =ROUND(3958.8*5280*ACOS(MIN(1,MAX(-1,SIN(RADIANS(Locations!$B13))*SIN(RADIANS(Locations!$B12))+COS(RADIANS(Locations!$B13))*COS(RADIANS(Locations!$B12))*COS(RADIANS(Locations!$C12-Locations!$C13))))),0) -> 1666 | M13: =0 -> 0 | N13: =ROUND(3958.8*5280*ACOS(MIN(1,MAX(-1,SIN(RADIANS(Locations!$B13))*SIN(RADIANS(Locations!$B14))+COS(RADIANS(Locations!$B13))*COS(RADIANS(Locations!$B14))*COS(RADIANS(Locations!$C14-Locations!$C13))))),0) -> 1526 | O13: =ROUND(3958.8*5280*ACOS(MIN(1,MAX(-1,SIN(RADIANS(Locations!$B13))*SIN(RADIANS(Locations!$B15))+COS(RADIANS(Locations!$B13))*COS(RADIANS(Locations!$B15))*COS(RADIANS(Locations!$C15-Locations!$C13))))),0) -> 1273 | P13: =ROUND(3958.8*5280*ACOS(MIN(1,MAX(-1,SIN(RADIANS(Locations!$B13))*SIN(RADIANS(Locations!$B16))+COS(RADIANS(Locations!$B13))*COS(RADIANS(Locations!$B16))*COS(RADIANS(Locations!$C16-Locations!$C13))))),0) -> 1230 | Q13: =ROUND(3958.8*5280*ACOS(MIN(1,MAX(-1,SIN(RADIANS(Locations!$B13))*SIN(RADIANS(Locations!$B17))+COS(RADIANS(Locations!$B13))*COS(RADIANS(Locations!$B17))*COS(RADIANS(Locations!$C17-Locations!$C13))))),0) -> 1507 | R13: =ROUND(3958.8*5280*ACOS(MIN(1,MAX(-1,SIN(RADIANS(Locations!$B13))*SIN(RADIANS(Locations!$B18))+COS(RADIANS(Locations!$B13))*COS(RADIANS(Locations!$B18))*COS(RADIANS(Locations!$C18-Locations!$C13))))),0) -> 2942 | S13: =ROUND(3958.8*5280*ACOS(MIN(1,MAX(-1,SIN(RADIANS(Locations!$B13))*SIN(RADIANS(Locations!$B19))+COS(RADIANS(Locations!$B13))*COS(RADIANS(Locations!$B19))*COS(RADIANS(Locations!$C19-Locations!$C13))))),0) -> 3238 | T13: =ROUND(3958.8*5280*ACOS(MIN(1,MAX(-1,SIN(RADIANS(Locations!$B13))*SIN(RADIANS(Locations!$B20))+COS(RADIANS(Locations!$B13))*COS(RADIANS(Locations!$B20))*COS(RADIANS(Locations!$C20-Locations!$C13))))),0) -> 2759
A14: =Locations!A14 -> Verano | B14: =ROUND(3958.8*5280*ACOS(MIN(1,MAX(-1,SIN(RADIANS(Locations!$B14))*SIN(RADIANS(Locations!$B2))+COS(RADIANS(Locations!$B14))*COS(RADIANS(Locations!$B2))*COS(RADIANS(Locations!$C2-Locations!$C14))))),0) -> 3537 | C14: =ROUND(3958.8*5280*ACOS(MIN(1,MAX(-1,SIN(RADIANS(Locations!$B14))*SIN(RADIANS(Locations!$B3))+COS(RADIANS(Locations!$B14))*COS(RADIANS(Locations!$B3))*COS(RADIANS(Locations!$C3-Locations!$C14))))),0) -> 3501 | D14: =ROUND(3958.8*5280*ACOS(MIN(1,MAX(-1,SIN(RADIANS(Locations!$B14))*SIN(RADIANS(Locations!$B4))+COS(RADIANS(Locations!$B14))*COS(RADIANS(Locations!$B4))*COS(RADIANS(Locations!$C4-Locations!$C14))))),0) -> 4104 | E14: =ROUND(3958.8*5280*ACOS(MIN(1,MAX(-1,SIN(RADIANS(Locations!$B14))*SIN(RADIANS(Locations!$B5))+COS(RADIANS(Locations!$B14))*COS(RADIANS(Locations!$B5))*COS(RADIANS(Locations!$C5-Locations!$C14))))),0) -> 3484 | F14: =ROUND(3958.8*5280*ACOS(MIN(1,MAX(-1,SIN(RADIANS(Locations!$B14))*SIN(RADIANS(Locations!$B6))+COS(RADIANS(Locations!$B14))*COS(RADIANS(Locations!$B6))*COS(RADIANS(Locations!$C6-Locations!$C14))))),0) -> 3446 | G14: =ROUND(3958.8*5280*ACOS(MIN(1,MAX(-1,SIN(RADIANS(Locations!$B14))*SIN(RADIANS(Locations!$B7))+COS(RADIANS(Locations!$B14))*COS(RADIANS(Locations!$B7))*COS(RADIANS(Locations!$C7-Locations!$C14))))),0) -> 2936 | H14: =ROUND(3958.8*5280*ACOS(MIN(1,MAX(-1,SIN(RADIANS(Locations!$B14))*SIN(RADIANS(Locations!$B8))+COS(RADIANS(Locations!$B14))*COS(RADIANS(Locations!$B8))*COS(RADIANS(Locations!$C8-Locations!$C14))))),0) -> 2672 | I14: =ROUND(3958.8*5280*ACOS(MIN(1,MAX(-1,SIN(RADIANS(Locations!$B14))*SIN(RADIANS(Locations!$B9))+COS(RADIANS(Locations!$B14))*COS(RADIANS(Locations!$B9))*COS(RADIANS(Locations!$C9-Locations!$C14))))),0) -> 2520 | J14: =ROUND(3958.8*5280*ACOS(MIN(1,MAX(-1,SIN(RADIANS(Locations!$B14))*SIN(RADIANS(Locations!$B10))+COS(RADIANS(Locations!$B14))*COS(RADIANS(Locations!$B10))*COS(RADIANS(Locations!$C10-Locations!$C14))))),0) -> 2907 | K14: =ROUND(3958.8*5280*ACOS(MIN(1,MAX(-1,SIN(RADIANS(Locations!$B14))*SIN(RADIANS(Locations!$B11))+COS(RADIANS(Locations!$B14))*COS(RADIANS(Locations!$B11))*COS(RADIANS(Locations!$C11-Locations!$C14))))),0) -> 5202 | L14: =ROUND(3958.8*5280*ACOS(MIN(1,MAX(-1,SIN(RADIANS(Locations!$B14))*SIN(RADIANS(Locations!$B12))+COS(RADIANS(Locations!$B14))*COS(RADIANS(Locations!$B12))*COS(RADIANS(Locations!$C12-Locations!$C14))))),0) -> 2110 | M14: =ROUND(3958.8*5280*ACOS(MIN(1,MAX(-1,SIN(RADIANS(Locations!$B14))*SIN(RADIANS(Locations!$B13))+COS(RADIANS(Locations!$B14))*COS(RADIANS(Locations!$B13))*COS(RADIANS(Locations!$C13-Locations!$C14))))),0) -> 1526 | N14: =0 -> 0 | O14: =ROUND(3958.8*5280*ACOS(MIN(1,MAX(-1,SIN(RADIANS(Locations!$B14))*SIN(RADIANS(Locations!$B15))+COS(RADIANS(Locations!$B14))*COS(RADIANS(Locations!$B15))*COS(RADIANS(Locations!$C15-Locations!$C14))))),0) -> 979 | P14: =ROUND(3958.8*5280*ACOS(MIN(1,MAX(-1,SIN(RADIANS(Locations!$B14))*SIN(RADIANS(Locations!$B16))+COS(RADIANS(Locations!$B14))*COS(RADIANS(Locations!$B16))*COS(RADIANS(Locations!$C16-Locations!$C14))))),0) -> 1333 | Q14: =ROUND(3958.8*5280*ACOS(MIN(1,MAX(-1,SIN(RADIANS(Locations!$B14))*SIN(RADIANS(Locations!$B17))+COS(RADIANS(Locations!$B14))*COS(RADIANS(Locations!$B17))*COS(RADIANS(Locations!$C17-Locations!$C14))))),0) -> 1319 | R14: =ROUND(3958.8*5280*ACOS(MIN(1,MAX(-1,SIN(RADIANS(Locations!$B14))*SIN(RADIANS(Locations!$B18))+COS(RADIANS(Locations!$B14))*COS(RADIANS(Locations!$B18))*COS(RADIANS(Locations!$C18-Locations!$C14))))),0) -> 2220 | S14: =ROUND(3958.8*5280*ACOS(MIN(1,MAX(-1,SIN(RADIANS(Locations!$B14))*SIN(RADIANS(Locations!$B19))+COS(RADIANS(Locations!$B14))*COS(RADIANS(Locations!$B19))*COS(RADIANS(Locations!$C19-Locations!$C14))))),0) -> 2158 | T14: =ROUND(3958.8*5280*ACOS(MIN(1,MAX(-1,SIN(RADIANS(Locations!$B14))*SIN(RADIANS(Locations!$B20))+COS(RADIANS(Locations!$B14))*COS(RADIANS(Locations!$B20))*COS(RADIANS(Locations!$C20-Locations!$C14))))),0) -> 1656
A15: =Locations!A15 -> Arroyo Vista | B15: =ROUND(3958.8*5280*ACOS(MIN(1,MAX(-1,SIN(RADIANS(Locations!$B15))*SIN(RADIANS(Locations!$B2))+COS(RADIANS(Locations!$B15))*COS(RADIANS(Locations!$B2))*COS(RADIANS(Locations!$C2-Locations!$C15))))),0) -> 3186 | C15: =ROUND(3958.8*5280*ACOS(MIN(1,MAX(-1,SIN(RADIANS(Locations!$B15))*SIN(RADIANS(Locations!$B3))+COS(RADIANS(Locations!$B15))*COS(RADIANS(Locations!$B3))*COS(RADIANS(Locations!$C3-Locations!$C15))))),0) -> 3060 | D15: =ROUND(3958.8*5280*ACOS(MIN(1,MAX(-1,SIN(RADIANS(Locations!$B15))*SIN(RADIANS(Locations!$B4))+COS(RADIANS(Locations!$B15))*COS(RADIANS(Locations!$B4))*COS(RADIANS(Locations!$C4-Locations!$C15))))),0) -> 3692 | E15: =ROUND(3958.8*5280*ACOS(MIN(1,MAX(-1,SIN(RADIANS(Locations!$B15))*SIN(RADIANS(Locations!$B5))+COS(RADIANS(Locations!$B15))*COS(RADIANS(Locations!$B5))*COS(RADIANS(Locations!$C5-Locations!$C15))))),0) -> 2917 | F15: =ROUND(3958.8*5280*ACOS(MIN(1,MAX(-1,SIN(RADIANS(Locations!$B15))*SIN(RADIANS(Locations!$B6))+COS(RADIANS(Locations!$B15))*COS(RADIANS(Locations!$B6))*COS(RADIANS(Locations!$C6-Locations!$C15))))),0) -> 3153 | G15: =ROUND(3958.8*5280*ACOS(MIN(1,MAX(-1,SIN(RADIANS(Locations!$B15))*SIN(RADIANS(Locations!$B7))+COS(RADIANS(Locations!$B15))*COS(RADIANS(Locations!$B7))*COS(RADIANS(Locations!$C7-Locations!$C15))))),0) -> 2829 | H15: =ROUND(3958.8*5280*ACOS(MIN(1,MAX(-1,SIN(RADIANS(Locations!$B15))*SIN(RADIANS(Locations!$B8))+COS(RADIANS(Locations!$B15))*COS(RADIANS(Locations!$B8))*COS(RADIANS(Locations!$C8-Locations!$C15))))),0) -> 2578 | I15: =ROUND(3958.8*5280*ACOS(MIN(1,MAX(-1,SIN(RADIANS(Locations!$B15))*SIN(RADIANS(Locations!$B9))+COS(RADIANS(Locations!$B15))*COS(RADIANS(Locations!$B9))*COS(RADIANS(Locations!$C9-Locations!$C15))))),0) -> 2100 | J15: =ROUND(3958.8*5280*ACOS(MIN(1,MAX(-1,SIN(RADIANS(Locations!$B15))*SIN(RADIANS(Locations!$B10))+COS(RADIANS(Locations!$B15))*COS(RADIANS(Locations!$B10))*COS(RADIANS(Locations!$C10-Locations!$C15))))),0) -> 2498 | K15: =ROUND(3958.8*5280*ACOS(MIN(1,MAX(-1,SIN(RADIANS(Locations!$B15))*SIN(RADIANS(Locations!$B11))+COS(RADIANS(Locations!$B15))*COS(RADIANS(Locations!$B11))*COS(RADIANS(Locations!$C11-Locations!$C15))))),0) -> 5126 | L15: =ROUND(3958.8*5280*ACOS(MIN(1,MAX(-1,SIN(RADIANS(Locations!$B15))*SIN(RADIANS(Locations!$B12))+COS(RADIANS(Locations!$B15))*COS(RADIANS(Locations!$B12))*COS(RADIANS(Locations!$C12-Locations!$C15))))),0) -> 2581 | M15: =ROUND(3958.8*5280*ACOS(MIN(1,MAX(-1,SIN(RADIANS(Locations!$B15))*SIN(RADIANS(Locations!$B13))+COS(RADIANS(Locations!$B15))*COS(RADIANS(Locations!$B13))*COS(RADIANS(Locations!$C13-Locations!$C15))))),0) -> 1273 | N15: =ROUND(3958.8*5280*ACOS(MIN(1,MAX(-1,SIN(RADIANS(Locations!$B15))*SIN(RADIANS(Locations!$B14))+COS(RADIANS(Locations!$B15))*COS(RADIANS(Locations!$B14))*COS(RADIANS(Locations!$C14-Locations!$C15))))),0) -> 979 | O15: =0 -> 0 | P15: =ROUND(3958.8*5280*ACOS(MIN(1,MAX(-1,SIN(RADIANS(Locations!$B15))*SIN(RADIANS(Locations!$B16))+COS(RADIANS(Locations!$B15))*COS(RADIANS(Locations!$B16))*COS(RADIANS(Locations!$C16-Locations!$C15))))),0) -> 371 | Q15: =ROUND(3958.8*5280*ACOS(MIN(1,MAX(-1,SIN(RADIANS(Locations!$B15))*SIN(RADIANS(Locations!$B17))+COS(RADIANS(Locations!$B15))*COS(RADIANS(Locations!$B17))*COS(RADIANS(Locations!$C17-Locations!$C15))))),0) -> 370 | R15: =ROUND(3958.8*5280*ACOS(MIN(1,MAX(-1,SIN(RADIANS(Locations!$B15))*SIN(RADIANS(Locations!$B18))+COS(RADIANS(Locations!$B15))*COS(RADIANS(Locations!$B18))*COS(RADIANS(Locations!$C18-Locations!$C15))))),0) -> 1690 | S15: =ROUND(3958.8*5280*ACOS(MIN(1,MAX(-1,SIN(RADIANS(Locations!$B15))*SIN(RADIANS(Locations!$B19))+COS(RADIANS(Locations!$B15))*COS(RADIANS(Locations!$B19))*COS(RADIANS(Locations!$C19-Locations!$C15))))),0) -> 1974 | T15: =ROUND(3958.8*5280*ACOS(MIN(1,MAX(-1,SIN(RADIANS(Locations!$B15))*SIN(RADIANS(Locations!$B20))+COS(RADIANS(Locations!$B15))*COS(RADIANS(Locations!$B20))*COS(RADIANS(Locations!$C20-Locations!$C15))))),0) -> 1512
